Workbook

Sheet Version
B2: ICTV 2024 Virus Metadata Resource (VMR)
B4: Editor: | C4: Donald Smith | E4: Send corrections to:
E5: donald.smith.ictv@gmail.com
B7: Version: | C7: MSL40.v1 | E7: =CONCATENATE("Version ",C7) -> Version MSL40.v1
B8: Date | C8: 45723 | E8: New MSL, #40 including all taxa updates since the 2023 release
B9: Change: | C9: Original release | E9: Updated all taxon names to match changes in MSL40.
E10: Added new isolates included in proposals for MSL40.
E11: Remove isolates in species that were abolished for MSL40.
E12: =HYPERLINK("https://ictv.global/vmr","For more information see: https://ictv.global/vmr") -> For more information see: https://ictv.global/vmr
B14: Version: | C14: MSL40.v2 | E14: =CONCATENATE("Version ",C14) -> Version MSL40.v2
B15: Date | C15: 45943 | E15: Minor MSL update, #40.v2:
B16: Change: | C16: Update | E16: Updated all taxon names to match changes in MSL40.v2
E17: Remove isolates in species that were abolished for MSL40.v2
E18: VMR updates:
E19: Various minor edits as detailed on README page, including making unique virus names for viruses in Anelloviridae, accession labels for Secoviridae and Begomovirus, reduced entries for Adenoviridae to AC_ accession only where available, Botourmiaviridae Protist host changed to unknown(S)
E20: =HYPERLINK("https://ictv.global/vmr","For more information see: https://ictv.global/vmr") -> For more information see: https://ictv.global/vmr

Sheet VMR MSL40
A1: Isolate ID | B1: Species Sort | C1: Isolate Sort | D1: Realm | E1: Subrealm | F1: Kingdom | G1: Subkingdom | H1: Phylum | I1: Subphylum | J1: Class | K1: Subclass | L1: Order | M1: Suborder | N1: Family | O1: Subfamily | P1: Genus | Q1: Subgenus | R1: Species | S1: ICTV_ID | T1: Exemplar or additional isolate | U1: Virus name(s) | V1: Virus name abbreviation(s) | W1: Virus isolate designation | X1: Virus GENBANK accession | Y1: Genome coverage | Z1: Genome | AA1: Host source | AB1: Accessions Link | AC1: Editor Notes | AD1: QC_status | AE1: QC_taxon_inher_molecule | AF1: QC_taxon_change | AG1: QC_taxon_proposal | AH1: =_xlfn.CONCAT("#𝚫"," ",SUM(AH2:AH1048576)) -> #𝚫 0 | AI1: 𝚫s
A2: =HYPERLINK("https://ictv.global/id/VMR1028127","VMR1028127") -> VMR1028127 | B2: 1 | C2: 1 | D2: Adnaviria | F2: Zilligvirae | H2: Taleaviricota | J2: Tokiviricetes | L2: Ligamenvirales | N2: Chiyouviridae | P2: Wargodvirus | R2: Wargodvirus xiongnu | S2: =HYPERLINK("https://ictv.global/id/ICTV202420188","ICTV202420188") -> ICTV202420188 | T2: E | U2: Bathyarchaeia bifangarchaeales chiyouvirus 1 | V2: BbCV1 | X2: PP467602 | Y2: Complete genome | Z2: dsDNA | AA2: archaea | AB2: =HYPERLINK("https://www.ncbi.nlm.nih.gov/nuccore/PP467602","NCBI Nucleotide") -> NCBI Nucleotide | AE2: dsDNA | AF2: created | AG2: =HYPERLINK("https://ictv.global/ictv/proposals/2024.005A.Bathyarchaeia_4newfam.zip","2024.005A.Bathyarchaeia_4newfam.zip") -> 2024.005A.Bathyarchaeia_4newfam.zip | AH2: =IF(AND(LEN($A2)=0,LEN($R2)>0),"1",INDEX(Original!AH:AH,MATCH($A2,Original!$A:$A,0))) -> 0 | AI2: =IF(AND(LEN($A2)=0,LEN($R2)>0),"new isolate",INDEX(Original!AI:AI,MATCH($A2,Original!$A:$A,0)))

Sheet Column definitions
A1: Column | B1: Heading | C1: Definition
A2: A | B2: Isolate ID | C2: ICTV unique isolate ID for each line of the VMR. This ID will only change if accessions are added or removed from the set of accessions that define the isolate's genome.
A3: B | B3: Species Sort | C3: ICTV internal sort ID of each virus species.
A4: C | B4: Isolate Sort | C4: ICTV internal sort ID of virus isolates within each species.
A5: D - R | B5: Realm, Subrealm, Kingdom, Subkingdom, Phylum, Subphylum, Class, Subclass, Order, Suborder, Family, Subfamily, Genus, Subgenus, Species | C5: Taxonomic ranks into which virus species are classified.
A6: S | B6: ICTV_ID | C6: ICTV unique taxon ID for the species. This ID will only change if a species is split into multiple species, or if several species are merged into one. It is not changed by renames or changes to the higher rank taxonomy in which the species is classified.
A7: T | B7: Exemplar or additional isolate | C7: Exemplar (E) or additional (A) isolate chosen by ICTV Study Groups as representative, well-characterised isolates of each species.
A8: U | B8: Virus name(s) | C8: Commonly used virus name (or names separated by a semi-colon).
A9: V | B9: Virus name abbreviation(s) | C9: Commonly used virus name abbreviation (or abbreviations separated by a semi-colon).
A10: W | B10: Virus isolate designation | C10: The designation of that particular virus isolate, variant or strain.
A11: X | B11: Virus GENBANK accession | C11: The GenBank (nucleotide) accession number (or numbers separted by a semicolon) for that virus isolate. In some cases a range within the accession sequence is specified by a "(startPos.endPos)" suffix.
A12: Y | B12: Genome coverage | C12: Genome coverage of the indicated virus. Possible values are: - Complete genome - Coding-complete genome - Partial genome (non-compliant) - No entry in Genbank
... A15: AB | B15: Accessions Link | C15: Link to the GenBank record(s) in columns X.
C17: See corresponding suffixes for the different ranks of satellite nucleic acids, viroids and viriforms in the ICTV Code (https://ictv.global/about/code) sections V, and VI

Sheet Column Values
A1: Exemplar or additional isolate | B1: Genome coverage | C1: Genome | D1: Host source
A2: E | B2: Complete genome | C2: dsDNA | D2: air (S)
A3: A | B3: Coding-complete genome | C3: dsDNA-RT | D3: archaea
B4: Partial genome | C4: dsRNA | D4: bacteria
B5: No entry in Genbank | C5: ssDNA | D5: bacteria, invertebrates (S)
B6: Not Compliant | C6: ssDNA(-) | D6: bacteria, vertebrates (S)
C7: ssDNA(+) | D7: freshwater (S)
C8: ssDNA(+/-) | D8: fungi
C9: ssRNA | D9: fungi (S)
C10: ssRNA-RT | D10: invertebrates
C11: ssRNA(-) | D11: invertebrates (S)
C12: ssRNA(+) | D12: invertebrates, plants
C13: ssRNA(+/-) | D13: invertebrates, vertebrates
C14: ssRNA(-); ssRNA(+/-) | D14: marine (S)
D15: phytobiome (S)
D16: plants
D17: plants (S)
D18: protists
D19: protists (S)
D20: sewage (S)
D21: soil (S)
D22: unknown (S)
D23: vertebrates
D24: vertebrates (S)

Sheet README.editor
A1: Guidance and Conventions for Editors
A3: Inserting a new Isolate:
B4: 1. insert a blank row
B5: 2. leave first 2 columns blank: A:Isolate ID, B:Species_Sort
B6: 3. fill in lineage, most importantly M:Species
B7: 4. when you fill in M:Species, the whole line should turn greene
A9: Abolishing an Isolate:
B10: 1. change
A13: Accession Rules:
B14: "Additional" Isolates: no partial genome allowed.
B15: "Exemplar" Isoaltes: record only partial if no GenBank complete genome exists: partial entries should be labeled as "partial:ACCESSION" in GenBank_accessions field

Sheet CHANGELOG.editor
A1: when | B1: who | C1: what
A2: 45538 | B2: CurtisH@uab.edu | C2: Exported from PROD after fixes to accession ordering
C3: Add "Isolate ID" column; should be left blnak for new isolates.
C4: Compare values against shee "Original" to detect edits
C5: Add coloring and counts of edited columns (see #𝚫 in column AH)
C6: Add names of edied columns(see 𝚫s in column AI)
C7: Add Data Validation against allowed value lists in "Column Valued" sheet
C8: Add comparison of accession numbers to last VMR of MSL38.
A9: 45540 | B9: CurtisH@uab.edu | C9: Paste-Values to bring data from "VMR_MSL39_v4_for_DS_ds.xlsx" into augemented template.
A10: 45540 | B10: CurtisH@uab.edu | C10: Added change highlighitng tochanges of only spaces or capitalization
C11: Added change highlighting for new isolates (isolate_id="", species<>"")
A12: 45541 | B12: CurtisH@uab.edu | C12: Removed "algae" and "oomycetes" from Column Values:Host Source
A13: 45541 | B13: CurtisH@uab.edu | C13: update SQL generation columns on "Original", special code for species_name
A14: 45541 | B14: CurtisH@uab.edu | C14: Add insert_seq column for new isolates in 'VMNR MSL39' sheet.
A15: 45541 | B15: CurtisH@uab.edu | C15: insert sql not perfect: need cast(var as varbinary(max)) to get case senstiviity: test case is 1025717 isolate_names currnetly: original is original, and VMR is from db; need to re-paste DS VMR and fix SQL, then update db, re-export, double check
A16: 45544 | B16: CurtisH@uab.edu | C16: format "species_name" and "Accession Link" as hotlinks (blue, under)
A17: 45544 | B17: CurtisH@uab.edu | C17: Update 'VMR MSL39' and 'Original' to match PROD database and all edits from 'VMR_MSL39_v4_for_DS_dbs.xlsx', including 2 new isolates
A18: 45547 | B18: CurtisH@uab.edu | C18: Update PROD db with VMR_MSL39_v4_for_DS_dbs_dbs_rch.xlsx, including new isolates and a new molecule type 'ssRNA(-); ssRNA(+/-)'; export PROD.[vmr_export] back into this file [VMR MSL39, Original]
A19: 45551 | B19: CurtisH@uab.edu | C19: Update PROD with additional RefSeqs listed in Donald Smith's Additional_ref_seqs_5.9.24.tsv and re-export VMR to Excel. RefSeq accessions were integrated by adding them to genbank_refseq_map_wide_fixed3.txt then using VMR_update_refseq.py to build a new VMR with correctly formatted and ordered RefSeq seg:accession lists.
A20: 45723 | B20: CurtisH@uab.edu | C20: Added segment names for Begomovirus sidaflavusfoli, which is a duplicate of the existing species/isolate, Begomovirus sidaflavusfolii, but that we caught only after ratification: DNA-A: MN013784; DNA-B: MN013785
A21: 45722 | B21: CurtisH@uab.edu | C21: Added isolates missing because proposals didn't have genome_coverage filled in
A22: 45719 | B22: CurtisH@uab.edu | C22: Correct initial round of errors caught by Donald Smith's QC scripts
A23: 45716 | B23: Curtish@uab.edu | C23: Update for MSL40v1
... A34: 45750 | B34: Donald Smith | C34: Adenoviridae, added back AC_seq for M73260
C35: Delete row for VMR1012218 duplicate entry
C36: Potexvirus ecsadenii - took one of two exemplar viruses as additional virus
C37: Pimascovirales - edits as in TP supplementary sheet and emails to J-M Claverie
A38: 45763 | B38: Donald Smith | C38: Format/length of virus names, abbreviations, accessions corrected as identified by script
C39: TP corrections from Lusia for plant viruses email 15th April
C40: TP corections from J-M Claverie email 10th April
A41: 45798 | B41: Donald Smith | C41: Added two Secoviridae isolate accessions
A42: 45803 | B42: Donald Smith | C42: Changed E isolate for Cypovirus antheraea
A43: 45860 | B43: Donald Smith | C43: Added accession labels for Secoviridae and Begomovirus, minor virus name edits KP638402 and Orthotospovirus hippeflavi
A44: 45943 | B44: Donald Smith | C44: Removed original accessions from Adenovirus AC_ entries
A45: 45943 | B45: Donald Smith | C45: Minor edits to Cystoviridae, Rhabdoviridae, Tospoviridae, Phenuiviridae
A46: 45943 | B46: Donald Smith | C46: Anelloviridae - made virus names unique by adding isolate name; some initial capital letters removed from virus names
A47: 45944 | B47: CurtisH@uab.edu | C47: kangaroo rat adenovirus (BK067721): update coverage to complete; add editor's notes for 2 species that were removed in MSL40v2, so whose updates are irrelevent: Trabzonvirus APT65 & Begomovirus sidaflavusfolii
A48: 45952 | B48: CurtisH@uab.edu | C48: Loaded changes into `ictv_taxonomy`.`species_isolates` and re-exported to create new MSL.xlsx. This incorporates changes made in MSL40.v2. Reset "Original" sheet. Set columns "Virus Names":"Abbr" to be TEXT, instead of GENERAL formatting.
A49: 45954 | B49: CurtisH@uab.edu | C49: Update data to correct `Species Sort` and `Isolate Sort` ordering. Fix change highlighting on "Column Values" worksheet so evertyhing doesn't turn red when you delete the "Original Column Values" worksheet; update formulas for calcualting deltas on "VMR MSL40" and "Original" so that field name AND original field value are given.
A50: 46036 | B50: Donald Smith | C50: Virus names altered so that are now unique for exemplars. Abbreviations that do not match virus names corrected. Some typos corrected.
...

Sheet Original
A1: Isolate ID | B1: Species Sort | C1: Isolate Sort | D1: Realm | E1: Subrealm | F1: Kingdom | G1: Subkingdom | H1: Phylum | I1: Subphylum | J1: Class | K1: Subclass | L1: Order | M1: Suborder | N1: Family | O1: Subfamily | P1: Genus | Q1: Subgenus | R1: Species | S1: ICTV_ID | T1: Exemplar or additional isolate | U1: Virus name(s) | V1: Virus name abbreviation(s) | W1: Virus isolate designation | X1: Virus GENBANK accession | Y1: Genome coverage | Z1: Genome | AA1: Host source | AB1: Accessions Link | AC1: Editor Notes | AD1: QC_status | AE1: QC_taxon_inher_molecule | AF1: QC_taxon_change | AG1: QC_taxon_proposal | AH1: #𝚫 | AI1: 𝚫s | AJ1: =B1 -> Species Sort | AK1: =C1 -> Isolate Sort | AL1: =D1 -> Realm | AM1: =E1 -> Subrealm | AN1: =F1 -> Kingdom | AO1: =G1 -> Subkingdom | AP1: =H1 -> Phylum | AQ1: =I1 -> Subphylum | ... BO1: =AG1 -> QC_taxon_proposal
A2: =HYPERLINK("https://ictv.global/id/VMR1028127","VMR1028127") -> VMR1028127 | B2: 1 | C2: 1 | D2: Adnaviria | F2: Zilligvirae | H2: Taleaviricota | J2: Tokiviricetes | L2: Ligamenvirales | N2: Chiyouviridae | P2: Wargodvirus | R2: Wargodvirus xiongnu | S2: =HYPERLINK("https://ictv.global/id/ICTV202420188","ICTV202420188") -> ICTV202420188 | T2: E | U2: Bathyarchaeia bifangarchaeales chiyouvirus 1 | V2: BbCV1 | X2: PP467602 | Y2: Complete genome | Z2: dsDNA | AA2: archaea | AB2: =HYPERLINK("https://www.ncbi.nlm.nih.gov/nuccore/PP467602","NCBI Nucleotide") -> NCBI Nucleotide | AE2: dsDNA | AF2: created | AG2: =HYPERLINK("https://ictv.global/ictv/proposals/2024.005A.Bathyarchaeia_4newfam.zip","2024.005A.Bathyarchaeia_4newfam.zip") -> 2024.005A.Bathyarchaeia_4newfam.zip | AH2: =COUNTIF(AJ2:BO2,"?*") -> 0 | AI2: =_xlfn.TEXTJOIN(",",TRUE,AJ2:BO2) | AJ2: =IF(NOT(EXACT(B2,INDEX('VMR MSL40'!B:B,MATCH($A2,'VMR MSL40'!$A:$A,0)))),AJ$1,"") | AK2: =IF(NOT(EXACT(C2,INDEX('VMR MSL40'!C:C,MATCH($A2,'VMR MSL40'!$A:$A,0)))),_xlfn.CONCAT(AK$1,":",C2),"") | AL2: =IF(NOT(EXACT(D2,INDEX('VMR MSL40'!D:D,MATCH($A2,'VMR MSL40'!$A:$A,0)))),_xlfn.CONCAT(AL$1,":",D2),"") | AM2: =IF(NOT(EXACT(E2,INDEX('VMR MSL40'!E:E,MATCH($A2,'VMR MSL40'!$A:$A,0)))),_xlfn.CONCAT(AM$1,":",E2),"") | AN2: =IF(NOT(EXACT(F2,INDEX('VMR MSL40'!F:F,MATCH($A2,'VMR MSL40'!$A:$A,0)))),_xlfn.CONCAT(AN$1,":",F2),"") | AO2: =IF(NOT(EXACT(G2,INDEX('VMR MSL40'!G:G,MATCH($A2,'VMR MSL40'!$A:$A,0)))),_xlfn.CONCAT(AO$1,":",G2),"") | AP2: =IF(NOT(EXACT(H2,INDEX('VMR MSL40'!H:H,MATCH($A2,'VMR MSL40'!$A:$A,0)))),_xlfn.CONCAT(AP$1,":",H2),"") | AQ2: =IF(NOT(EXACT(I2,INDEX('VMR MSL40'!I:I,MATCH($A2,'VMR MSL40'!$A:$A,0)))),_xlfn.CONCAT(AQ$1,":",I2),"") | AR2: =IF(NOT(EXACT(J2,INDEX('VMR MSL40'!J:J,MATCH($A2,'VMR MSL40'!$A:$A,0)))),_xlfn.CONCAT(AR$1,":",J2),"") | AS2: =IF(NOT(EXACT(K2,INDEX('VMR MSL40'!K:K,MATCH($A2,'VMR MSL40'!$A:$A,0)))),_xlfn.CONCAT(AS$1,":",K2),"") | AT2: =IF(NOT(EXACT(L2,INDEX('VMR MSL40'!L:L,MATCH($A2,'VMR MSL40'!$A:$A,0)))),_xlfn.CONCAT(AT$1,":",L2),"") | AU2: =IF(NOT(EXACT(M2,INDEX('VMR MSL40'!M:M,MATCH($A2,'VMR MSL40'!$A:$A,0)))),_xlfn.CONCAT(AU$1,":",M2),"") | AV2: =IF(NOT(EXACT(N2,INDEX('VMR MSL40'!N:N,MATCH($A2,'VMR MSL40'!$A:$A,0)))),_xlfn.CONCAT(AV$1,":",N2),"") | AW2: =IF(NOT(EXACT(O2,INDEX('VMR MSL40'!O:O,MATCH($A2,'VMR MSL40'!$A:$A,0)))),_xlfn.CONCAT(AW$1,":",O2),"") | AX2: =IF(NOT(EXACT(P2,INDEX('VMR MSL40'!P:P,MATCH($A2,'VMR MSL40'!$A:$A,0)))),_xlfn.CONCAT(AX$1,":",P2),"") | AY2: =IF(NOT(EXACT(Q2,INDEX('VMR MSL40'!Q:Q,MATCH($A2,'VMR MSL40'!$A:$A,0)))),_xlfn.CONCAT(AY$1,":",Q2),"") | AZ2: =IF(NOT(EXACT(R2,INDEX('VMR MSL40'!R:R,MATCH($A2,'VMR MSL40'!$A:$A,0)))),_xlfn.CONCAT(AZ$1,":",R2),"") | BB2: =IF(NOT(EXACT(T2,INDEX('VMR MSL40'!T:T,MATCH($A2,'VMR MSL40'!$A:$A,0)))),_xlfn.CONCAT(BB$1,":",T2),"") | BC2: =IF(NOT(EXACT(U2,INDEX('VMR MSL40'!U:U,MATCH($A2,'VMR MSL40'!$A:$A,0)))),_xlfn.CONCAT(BC$1,":",U2),"") | BD2: =IF(NOT(EXACT(V2,INDEX('VMR MSL40'!V:V,MATCH($A2,'VMR MSL40'!$A:$A,0)))),_xlfn.CONCAT(BD$1,":",V2),"") | BE2: =IF(NOT(EXACT(W2,INDEX('VMR MSL40'!W:W,MATCH($A2,'VMR MSL40'!$A:$A,0)))),_xlfn.CONCAT(BE$1,":",W2),"") | BF2: =IF(NOT(EXACT(X2,INDEX('VMR MSL40'!X:X,MATCH($A2,'VMR MSL40'!$A:$A,0)))),_xlfn.CONCAT(BF$1,":",X2),"") | BG2: =IF(NOT(EXACT(Y2,INDEX('VMR MSL40'!Y:Y,MATCH($A2,'VMR MSL40'!$A:$A,0)))),_xlfn.CONCAT(BG$1,":",Y2),"") | BH2: =IF(NOT(EXACT(Z2,INDEX('VMR MSL40'!Z:Z,MATCH($A2,'VMR MSL40'!$A:$A,0)))),_xlfn.CONCAT(BH$1,":",Z2),"") | BI2: =IF(NOT(EXACT(AA2,INDEX('VMR MSL40'!AA:AA,MATCH($A2,'VMR MSL40'!$A:$A,0)))),_xlfn.CONCAT(BI$1,":",AA2),"") | BK2: =IF(NOT(EXACT(AC2,INDEX('VMR MSL40'!AC:AC,MATCH($A2,'VMR MSL40'!$A:$A,0)))),_xlfn.CONCAT(BK$1,":",AC2),"")

Sheet Original Column Values
A1: Exemplar or additional isolate | B1: Genome coverage | C1: Genome | D1: Host source
A2: E | B2: Complete genome | C2: dsDNA | D2: air (S)
A3: A | B3: Coding-complete genome | C3: dsDNA-RT | D3: archaea
B4: Partial genome | C4: dsRNA | D4: bacteria
B5: No entry in Genbank | C5: ssDNA | D5: bacteria, invertebrates (S)
B6: Not Compliant | C6: ssDNA(-) | D6: bacteria, vertebrates (S)
C7: ssDNA(+) | D7: freshwater (S)
C8: ssDNA(+/-) | D8: fungi
C9: ssRNA | D9: fungi (S)
C10: ssRNA-RT | D10: invertebrates
C11: ssRNA(-) | D11: invertebrates (S)
C12: ssRNA(+) | D12: invertebrates, plants
C13: ssRNA(+/-) | D13: invertebrates, vertebrates
C14: ssRNA(-); ssRNA(+/-) | D14: marine (S)
D15: phytobiome (S)
D16: plants
D17: plants (S)
D18: protists
D19: protists (S)
D20: sewage (S)
D21: soil (S)
D22: unknown (S)
D23: vertebrates
D24: vertebrates (S)
